<?xml version="1.0"?>
<robot xmlns:xacro="http://www.ros.org/wiki/xacro">
    <!-- wheel properties -->
    <xacro:property name="wheel_radius" value="0.085"/>
    <xacro:property name="wheel_width" value="0.073"/>
    <xacro:property name="wheel_ygap" value="0.3928"/>
    <xacro:property name="wheel_zoff" value="0"/>
    <xacro:property name="wheel_xoff" value="0"/>
    <xacro:property name="wheel_cm" value="0.0 0.0 0.0"/>
    <xacro:property name="wheel_mass" value="3.75"/>
    <xacro:property name="wheel_ixx" value="0.008439"/>
    <xacro:property name="wheel_iyy" value="0.008439"/>
    <xacro:property name="wheel_izz" value="0.013547"/>
    <xacro:property name="wheel_ixy" value="0.0"/>
    <xacro:property name="wheel_ixz" value="0.0"/>
    <xacro:property name="wheel_iyz" value="0.0"/>
    <!-- Wheels -->
    <xacro:macro name="wheel" params="prefix x_reflect y_reflect">
        <link name="${prefix}_wheel">
            <visual>
                <origin xyz="0 0 0" rpy="${pi/2} 0 0"/>
                <geometry>
                    <cylinder radius="${wheel_radius}" length="${wheel_width}"/>
                </geometry>
                <material name="Gray">
                    <color rgba="0.5 0.5 0.5 1.0"/>
                </material>
            </visual>
            <collision>
                <origin xyz="0 0 0" rpy="${pi/2} 0 0"/>
                <geometry>
                    <cylinder radius="${wheel_radius}" length="${wheel_width}"/>
                </geometry>
            </collision>
            <inertial>
                <origin xyz="0.0 0.0 0.0"/>
                <mass value="${wheel_mass}"/>
                <inertia ixx="${wheel_ixx}" ixy="${wheel_ixy}" ixz="${wheel_ixz}" iyy="${wheel_iyy}" iyz="${wheel_iyy}" izz="${wheel_izz}"/>
            </inertial>
            
        </link>

        <joint name="${prefix}_wheel_joint" type="continuous">
            <parent link="base_link"/>
            <child link="${prefix}_wheel"/>
            <origin xyz="${x_reflect*wheel_xoff} ${y_reflect*(base_width/2+wheel_ygap)} ${-wheel_zoff}" rpy="0 0 0"/>
            <axis xyz="0 1 0"/>
        </joint>
    </xacro:macro>
</robot>